<?xml version="1.0" ?>
<sdf version="1.5">
  <model name="dogtooth_001">  
  <pose>0.0 0.0 0.0 0.0 0.0 0.0</pose>

    <link name="base_footprint"/>

    <link name="base_link">

      <inertial>
        <pose>-0.064 0 0.048 0 0 0</pose>
        <inertia>
          <ixx>8.7002718e-03</ixx>
          <ixy>0</ixy>
          <ixz>0</ixz>
          <iyy>4.2111447e-02</iyy>
          <iyz>0</iyz>
          <izz>7.5254874e-02</izz>
        </inertia>
        <mass>300.0</mass>
      </inertial>

      <collision name="base_collision">
        <pose>-0.064 0 0.048 0 0 0</pose>
        <geometry>
          <box>
            <size>0.265 0.265 0.089</size>
          </box>
        </geometry>
      </collision>


      <visual name="base_visual">
        <pose>-0.064 0 0 0 0 0</pose>
        <geometry>
          <mesh>
            <uri>model://dogtooth_common/meshes/chassis.dae</uri>
            <scale>1 1 1</scale>
          </mesh>
        </geometry>
      </visual>
    </link>

    <link name="imu_link">
      <sensor name="tb3_imu" type="imu">
        <always_on>true</always_on>
        <update_rate>200</update_rate>
        <imu>
          <angular_velocity>
            <x>
              <noise type="gaussian">
                <mean>0.0</mean>
                <stddev>2e-4</stddev>
              </noise>
            </x>
            <y>
              <noise type="gaussian">
                <mean>0.0</mean>
                <stddev>2e-4</stddev>
              </noise>
            </y>
            <z>
              <noise type="gaussian">
                <mean>0.0</mean>
                <stddev>2e-4</stddev>
              </noise>
            </z>
          </angular_velocity>
          <linear_acceleration>
            <x>
              <noise type="gaussian">
                <mean>0.0</mean>
                <stddev>1.7e-2</stddev>
              </noise>
            </x>
            <y>
              <noise type="gaussian">
                <mean>0.0</mean>
                <stddev>1.7e-2</stddev>
              </noise>
            </y>
            <z>
              <noise type="gaussian">
                <mean>0.0</mean>
                <stddev>1.7e-2</stddev>
              </noise>
            </z>
          </linear_acceleration>
        </imu>
        <plugin name="dogtooth_imu" filename="libgazebo_ros_imu_sensor.so">
          <ros>
            <!-- <namespace>/tb3</namespace> -->
            <remapping>~/out:=imu</remapping>
          </ros>
        </plugin>
      </sensor>
    </link>

    <link name="base_scan">    
      <inertial>
        <pose>1.2 0 0.5 0 0 -1.5</pose>

        <inertia>
          <ixx>0.001</ixx>
          <ixy>0.000</ixy>
          <ixz>0.000</ixz>
          <iyy>0.001</iyy>
          <iyz>0.000</iyz>
          <izz>0.001</izz>
        </inertia>
        <mass>0.0001</mass>
      </inertial>

      <collision name="lidar_sensor_collision">
        <pose>-0.052 0 0.111 0 0 0</pose>
        <geometry>
          <cylinder>
            <radius>0.0508</radius>
            <length>0.055</length>
          </cylinder>
        </geometry>
      </collision>

      <visual name="lidar_sensor_visual">
        <pose>1.2 0 0.5 0 0 -1.5</pose>
        <geometry>
          <mesh>
            <uri>model://dogtooth_common/meshes/lds.dae</uri>
            <scale>0.001 0.001 0.001</scale>
          </mesh>
        </geometry>
      </visual>

      <sensor name="hls_lfcd_lds" type="ray">
        <always_on>true</always_on>
        <visualize>true</visualize>
        <pose>1.2 0 0.5 0 0 -1.5</pose>
        <update_rate>5</update_rate>
        <ray>
            <scan>
              <horizontal>
                  <samples>360</samples>
                  <resolution>1.000000</resolution>
                  <min_angle>0.000000</min_angle>
                  <max_angle>3.140000</max_angle>
              </horizontal>
            </scan>
            <range>
            <min>0.80000</min>
            <max>3.5</max>
            <resolution>0.015000</resolution>
            </range>
            <noise>
            <type>gaussian</type>
            <mean>0.0</mean>
            <stddev>0.01</stddev>
            </noise>
        </ray>
        <plugin name="dogtooth_laserscan" filename="libgazebo_ros_ray_sensor.so">
          <ros>
            <!-- <namespace>/tb3</namespace> -->
            <remapping>~/out:=scan</remapping>
          </ros>
          <output_type>sensor_msgs/LaserScan</output_type>
          <frame_name>base_scan</frame_name>
        </plugin>
      </sensor>
    </link>

    <link name="wheel_left_link">

      <inertial>
        <pose>0.0 0.144 0.023 -1.57 0 0</pose>
        <inertia>
          <ixx>1.1175580e-05</ixx>
          <ixy>-4.2369783e-11</ixy>
          <ixz>-5.9381719e-09</ixz>
          <iyy>1.1192413e-05</iyy>
          <iyz>-1.4400107e-11</iyz>
          <izz>2.0712558e-05</izz>
        </inertia>
        <mass>0.1</mass>
      </inertial>

      <collision name="wheel_left_collision">
        <pose>0.0 0.144 0.023 -1.57 0 0</pose>
        <geometry>
          <cylinder>
            <radius>0.033</radius>
            <length>0.018</length>
          </cylinder>
        </geometry>
        <surface>
          <!-- This friction pamareter don't contain reliable data!! -->
          <friction>
            <ode>
              <mu>100000.0</mu>
              <mu2>100000.0</mu2>
              <fdir1>0 0 0</fdir1>
              <slip1>0.0</slip1>
              <slip2>0.0</slip2>
            </ode>
          </friction>
          <contact>
            <ode>
              <soft_cfm>0</soft_cfm>
              <soft_erp>0.2</soft_erp>
              <kp>1e+5</kp>
              <kd>1</kd>
              <max_vel>0.01</max_vel>
              <min_depth>0.001</min_depth>
            </ode>
          </contact>
        </surface>
      </collision>

      <visual name="wheel_left_visual">
        <pose>0.0 0.144 0.023 0 0 0</pose>
        <geometry>
          <mesh>
            <uri>model://dogtooth_common/meshes/wheel.dae</uri>
            <scale>0.001 0.001 0.001</scale>
          </mesh>
        </geometry>
      </visual>
    </link>

    <link name="wheel_right_link">

      <inertial>
        <pose>0.0 -0.144 0.023 -1.57 0 0</pose>
        <inertia>
          <ixx>1.1175580e-05</ixx>
          <ixy>-4.2369783e-11</ixy>
          <ixz>-5.9381719e-09</ixz>
          <iyy>1.1192413e-05</iyy>
          <iyz>-1.4400107e-11</iyz>
          <izz>2.0712558e-05</izz>
        </inertia>
        <mass>0.1</mass>
      </inertial>
    
      <collision name="wheel_right_collision">
        <pose>0.0 -0.144 0.023 -1.57 0 0</pose>
        <geometry>
          <cylinder>
            <radius>0.033</radius>
            <length>0.018</length>
          </cylinder>
        </geometry>
        <surface>
          <!-- This friction pamareter don't contain reliable data!! -->
          <friction>
            <ode>
              <mu>100000.0</mu>
              <mu2>100000.0</mu2>
              <fdir1>0 0 0</fdir1>
              <slip1>0.0</slip1>
              <slip2>0.0</slip2>
            </ode>
          </friction>
          <contact>
            <ode>
              <soft_cfm>0</soft_cfm>
              <soft_erp>0.2</soft_erp>
              <kp>1e+5</kp>
              <kd>1</kd>
              <max_vel>0.01</max_vel>
              <min_depth>0.001</min_depth>
            </ode>
          </contact>
        </surface>
      </collision>

      <visual name="wheel_right_visual">
        <pose>0.0 -0.144 0.023 0 0 0</pose>
        <geometry>
          <mesh>
            <uri>model://dogtooth_common/meshes/wheel.dae</uri>
            <scale>0.001 0.001 0.001</scale>
          </mesh>
        </geometry>
      </visual>
    </link>

    <link name='caster_back_right_link'>
      <pose>0.215 -0.263 0.096 -1.57 0 0</pose>
      <inertial>
        <mass>0.001</mass>
        <inertia>
          <ixx>0.00001</ixx>
          <ixy>0.000</ixy>
          <ixz>0.000</ixz>
          <iyy>0.00001</iyy>
          <iyz>0.000</iyz>
          <izz>0.00001</izz>
        </inertia>
      </inertial>
      <collision name='collision'>
        <geometry>
          <sphere>
            <radius>0.005000</radius>
          </sphere>
        </geometry>
        <surface>
          <contact>
            <ode>
              <soft_cfm>0</soft_cfm>
              <soft_erp>0.2</soft_erp>
              <kp>1e+5</kp>
              <kd>1</kd>
              <max_vel>0.01</max_vel>
              <min_depth>0.001</min_depth>
            </ode>
          </contact>
        </surface>
      </collision>
    </link>

    <link name='caster_back_left_link'>
      <pose>0.215 0.263 0.096 -1.57 0 0</pose>
      <inertial>
        <mass>0.001</mass>
        <inertia>
          <ixx>0.00001</ixx>
          <ixy>0.000</ixy>
          <ixz>0.000</ixz>
          <iyy>0.00001</iyy>
          <iyz>0.000</iyz>
          <izz>0.00001</izz>
        </inertia>
      </inertial>
      <collision name='collision'>
        <geometry>
          <sphere>
            <radius>0.005000</radius>
          </sphere>
        </geometry>
        <surface>
          <contact>
            <ode>
              <soft_cfm>0</soft_cfm>
              <soft_erp>0.2</soft_erp>
              <kp>1e+5</kp>
              <kd>1</kd>
              <max_vel>0.01</max_vel>
              <min_depth>0.001</min_depth>
            </ode>
          </contact>
        </surface>
      </collision>
    </link>

    <link name="gps_link">
      <sensor name="dogtooth_gps" type="gps">
          <always_on>true</always_on>
          <update_rate>1</update_rate>
          <pose>0 0 0 0 0 0</pose>
          <gps>
            <position_sensing>
              <horizontal>
                <noise type="gaussian">
                  <mean>0.0</mean>
                  <stddev>0.01</stddev>
                </noise>
              </horizontal>
              <vertical>
                <noise type="gaussian">
                  <mean>0.0</mean>
                  <stddev>0.01</stddev>
                </noise>
              </vertical>
            </position_sensing>
          </gps>
          <plugin name="dogtooth_gps_plugin" filename="libgazebo_ros_gps_sensor.so">
            <ros>
              <remapping>~/out:=/gps/fix</remapping>
            </ros>
          </plugin>
        </sensor>
    </link>
    
    <joint name="gps_joint" type="fixed">
      <parent>base_link</parent>
      <child>gps_link</child>
      <pose>-0.032 0 0.1 0 0 0</pose>
      <axis>
        <xyz>0 0 1</xyz>
      </axis>
    </joint>    

   

    <joint name="base_joint" type="fixed">
      <parent>base_footprint</parent>
      <child>base_link</child>
      <pose>0.0 0.0 0.010 0 0 0</pose>
    </joint>

    <joint name="wheel_left_joint" type="revolute">
      <parent>base_link</parent>
      <child>wheel_left_link</child>
      <pose>-0.325 0.263 0.096 -1.57 0 0</pose>
      <axis>
        <xyz>0 0 1</xyz>
      </axis>
    </joint>

    <joint name="wheel_right_joint" type="revolute">
      <parent>base_link</parent>
      <child>wheel_right_link</child>
      <pose>-0.325 -0.263 0.096 -1.57 0 0</pose>
      <axis>
        <xyz>0 0 1</xyz>
      </axis>
    </joint>

    <joint name='caster_back_right_joint' type='ball'>
      <parent>base_link</parent>
      <child>caster_back_right_link</child>
    </joint>

    <joint name='caster_back_left_joint' type='ball'>
      <parent>base_link</parent>
      <child>caster_back_left_link</child>
    </joint>

    <joint name="imu_joint" type="fixed">
      <parent>base_link</parent>
      <child>imu_link</child>
      <pose>-0.032 0 0.068 0 0 0</pose>
      <axis>
        <xyz>0 0 1</xyz>
      </axis>
    </joint>    

    <joint name="lidar_joint" type="fixed">
      <parent>base_link</parent>
      <child>base_scan</child>
      <pose>-0.064 0 0.121 0 0 0</pose>
      <axis>
        <xyz>0 0 1</xyz>
      </axis>
    </joint>


    <link name="ultrasonic_1_link">
        <pose>0.0 0 0.3 0 0 0</pose>
        <inertial>
          <pose>0.0 0 0.3 0 0 0</pose>
          <inertia>
            <ixx>0.001</ixx>
            <ixy>0.000</ixy>
            <ixz>0.000</ixz>
            <iyy>0.001</iyy>
            <iyz>0.000</iyz>
            <izz>0.001</izz>
          </inertia>
          <mass>0.00001</mass>
        </inertial>
        <sensor name="ultrasonic_1" type="ray">
            <always_on>true</always_on>
            <visualize>true</visualize>
            <update_rate>5</update_rate>
            <ray>
            <scan>
                <horizontal>
                <samples>5</samples>
                <resolution>1.000000</resolution>
                <min_angle>-0.12</min_angle>
                <max_angle>0.12</max_angle>
                </horizontal>
                <vertical>
                <samples>5</samples>
                <resolution>1.000000</resolution>
                <min_angle>-0.01</min_angle>
                <max_angle>0.01</max_angle>
                </vertical>
            </scan>
            <range>
                <min>0.02</min>
                <max>3</max>
                <resolution>0.01</resolution>
            </range>
            <noise>
                <type>gaussian</type>
                <mean>0.0</mean>
                <stddev>0.01</stddev>
            </noise>
            </ray>
            <plugin name="ultrasonic_sensor_1" filename="libgazebo_ros_ray_sensor.so">
            <ros>
                <remapping>~/out:=ultrasonic_sensor_1</remapping>
            </ros>
            <output_type>sensor_msgs/Range</output_type>
            <radiation_type>ultrasound</radiation_type>
            <frame_name>ultrasonic_1_link</frame_name>
            </plugin>
        </sensor>  
    </link>

    <joint name="ultrasonic_1_joint" type="fixed">
      <parent>base_link</parent>
      <child>ultrasonic_1_link</child>
      <pose>0.0 0 0.3 0 0 0</pose>
      <axis>
        <xyz>0 0 1</xyz>
      </axis>
    </joint>   

    <link name="ultrasonic_2_link">
        <pose>0.0 0 0.3 0 0 3.14</pose>
         <inertial>
          <pose>0.0 0 0.3 0 0 3.14</pose>
          <inertia>
            <ixx>0.001</ixx>
            <ixy>0.000</ixy>
            <ixz>0.000</ixz>
            <iyy>0.001</iyy>
            <iyz>0.000</iyz>
            <izz>0.001</izz>
          </inertia>
          <mass>0.00001</mass>
        </inertial>
        <sensor name="ultrasonic_2" type="ray">
            <always_on>true</always_on>
            <visualize>true</visualize>
            <update_rate>5</update_rate>
            <ray>
            <scan>
                <horizontal>
                <samples>5</samples>
                <resolution>1.000000</resolution>
                <min_angle>-0.12</min_angle>
                <max_angle>0.12</max_angle>
                </horizontal>
                <vertical>
                <samples>5</samples>
                <resolution>1.000000</resolution>
                <min_angle>-0.01</min_angle>
                <max_angle>0.01</max_angle>
                </vertical>
            </scan>
            <range>
                <min>0.02</min>
                <max>3</max>
                <resolution>0.01</resolution>
            </range>
            <noise>
                <type>gaussian</type>
                <mean>0.0</mean>
                <stddev>0.01</stddev>
            </noise>
            </ray>
            <plugin name="ultrasonic_sensor_2" filename="libgazebo_ros_ray_sensor.so">
            <ros>
                <remapping>~/out:=ultrasonic_sensor_2</remapping>
            </ros>
            <output_type>sensor_msgs/Range</output_type>
            <radiation_type>ultrasound</radiation_type>
            <frame_name>ultrasonic_2_link</frame_name>
            </plugin>
        </sensor>  
    </link> 

    <joint name="ultrasonic_2_joint" type="fixed">
      <parent>base_link</parent>
      <child>ultrasonic_2_link</child>
      <pose>0.0 0 0.3 0 0 3.14</pose>
      <axis>
        <xyz>0 0 1</xyz>
      </axis>
    </joint>  


    <link name="front_camera_link">
      <inertial>
        <pose>1.2 0.0 0.9 0 0 0</pose>
        <inertia>
          <ixx>0.001</ixx>
          <ixy>0.000</ixy>
          <ixz>0.000</ixz>
          <iyy>0.001</iyy>
          <iyz>0.000</iyz>
          <izz>0.001</izz>
        </inertia>
        <mass>0.00001</mass>
      </inertial>

      <pose>1.2 0.0 0.9 0 0 0</pose>
      <sensor name="front_camera" type="depth">
        <always_on>1</always_on>
        <update_rate>1</update_rate>
        <!-- <pose>0.064 -0.047 0.107 0 0 0</pose> -->
        <camera name="front_camera">
        </camera>
	    <plugin name="front_camera_depth_driver" filename="libgazebo_ros_camera.so">
            <ros>
            </ros>
            <camera_name>front_camera</camera_name>
            <frame_name>front_camera_depth_frame</frame_name>
            <hack_baseline>0.07</hack_baseline>
            <min_depth>0.4</min_depth>
            <max_depth>8</max_depth>
        </plugin>
      </sensor>
      <sensor name="front_camera_rgb" type="camera">
        <always_on>true</always_on>
        <visualize>true</visualize>
        <update_rate>30</update_rate>
        <camera name="front_camera_rgb">
          <horizontal_fov>1.02974</horizontal_fov>
          <image>
            <width>1920</width>
            <height>1080</height>
            <format>R8G8B8</format>
          </image>
          <clip>
            <near>0.02</near>
            <far>300</far>
          </clip>
          <noise>
            <type>gaussian</type>
            <mean>0.0</mean>
            <stddev>0.007</stddev>
          </noise>
        </camera>
          <plugin name="front_camera_driver" filename="libgazebo_ros_camera.so">
            <ros>
            </ros>
            <camera_name>front_camera_rgb</camera_name>
            <frame_name>front_camera_rgb_frame</frame_name>
            <hack_baseline>0.07</hack_baseline>
          </plugin>
      </sensor>
    </link> 

    <link name="front_camera_rgb_frame"/>

    <joint name="front_camera_joint" type="fixed">
      <parent>base_link</parent>
      <child>front_camera_link</child>
      <pose>1.2 0.0 0.9 0 0 0</pose>
      <axis>
        <xyz>0 0 1</xyz>
      </axis>
    </joint>

    <joint name="front_camera_rgb_joint" type="fixed">
      <parent>front_camera_link</parent>
      <child>front_camera_rgb_frame</child>
      <pose>0.005 0.018 0.013 -1.57 0 -1.57</pose>
      <axis>
        <xyz>0 0 1</xyz>
      </axis>
    </joint>

    <joint name="front_camera_rgb_optical_joint" type="fixed">
      <parent>front_camera_rgb_frame</parent>
      <child>front_camera_rgb_optical_frame</child>
      <pose>0 0 0 -1.57 0 -1.57</pose>
      <axis>
        <xyz>0 0 1</xyz>
      </axis>
    </joint>

    <link name="front_camera_rgb_optical_frame"/>

    <joint name="front_camera_depth_joint" type="fixed">
      <parent>front_camera_link</parent>
      <child>front_camera_depth_frame</child>
      <pose>0.005 0.028 0.013 -1.57 0 -1.57</pose>
      <axis>
        <xyz>0 0 1</xyz>
      </axis>
    </joint>

    <link name="front_camera_depth_frame">
      <inertial>
        <pose>0.005 0.028 0.013 0 0 0</pose>
        <inertia>
          <ixx>0.001</ixx>
          <ixy>0.000</ixy>
          <ixz>0.000</ixz>
          <iyy>0.001</iyy>
          <iyz>0.000</iyz>
          <izz>0.001</izz>
        </inertia>
        <mass>0.0001</mass>
      </inertial>
    </link>

    <joint name="front_camera_depth_optical_joint" type="fixed">
      <parent>front_camera_depth_frame</parent>
      <child>front_camera_depth_optical_frame</child>
      <pose>0 0 0 -1.57 0 -1.57</pose>
      <axis>
        <xyz>0 0 1</xyz>
      </axis>
    </joint>

    <link name="front_camera_depth_optical_frame">
      <inertial>
        <pose>0 0 0 -1.57 0 -1.57</pose>
        <inertia>
          <ixx>0.001</ixx>
          <ixy>0.000</ixy>
          <ixz>0.000</ixz>
          <iyy>0.001</iyy>
          <iyz>0.000</iyz>
          <izz>0.001</izz>
        </inertia>
        <mass>0.00001</mass>
      </inertial>
    </link>

    <link name="back_camera_link">
      <inertial>
        <pose>-1.2 0.0 0.9 0 0 3.14</pose>
        <inertia>
          <ixx>0.001</ixx>
          <ixy>0.000</ixy>
          <ixz>0.000</ixz>
          <iyy>0.001</iyy>
          <iyz>0.000</iyz>
          <izz>0.001</izz>
        </inertia>
        <mass>0.00001</mass>
      </inertial>

      <pose>-1.2 0.0 0.9 0 0 3.14</pose>
      <sensor name="back_camera" type="depth">
        <always_on>1</always_on>
        <update_rate>1</update_rate>
        <!-- <pose>0.064 -0.047 0.107 0 0 0</pose> -->
        <camera name="back_camera">
        </camera>
	    <plugin name="back_camera_depth_driver" filename="libgazebo_ros_camera.so">
            <ros>
            </ros>
            <camera_name>back_camera</camera_name>
            <frame_name>back_camera_depth_frame</frame_name>
            <hack_baseline>0.07</hack_baseline>
            <min_depth>0.4</min_depth>
            <max_depth>8</max_depth>
        </plugin>
      </sensor>
      <sensor name="back_camera_rgb" type="camera">
        <always_on>true</always_on>
        <visualize>true</visualize>
        <update_rate>30</update_rate>
        <camera name="back_camera_rgb">
          <horizontal_fov>1.02974</horizontal_fov>
          <image>
            <width>1920</width>
            <height>1080</height>
            <format>R8G8B8</format>
          </image>
          <clip>
            <near>0.02</near>
            <far>300</far>
          </clip>
          <noise>
            <type>gaussian</type>
            <mean>0.0</mean>
            <stddev>0.007</stddev>
          </noise>
        </camera>
          <plugin name="back_camera_driver" filename="libgazebo_ros_camera.so">
            <ros>
            </ros>
            <camera_name>back_camera_rgb</camera_name>
            <frame_name>back_camera_rgb_frame</frame_name>
            <hack_baseline>0.07</hack_baseline>
          </plugin>
      </sensor>
    </link> 

    <link name="back_camera_rgb_frame"/>

    <joint name="back_camera_joint" type="fixed">
      <parent>base_link</parent>
      <child>back_camera_link</child>
      <pose>-1.2 0.0 0.9 0 0 3.14</pose>
      <axis>
        <xyz>0 0 1</xyz>
      </axis>
    </joint>

    <joint name="back_camera_rgb_joint" type="fixed">
      <parent>back_camera_link</parent>
      <child>back_camera_rgb_frame</child>
      <pose>0.005 0.018 0.013 -1.57 0 -1.57</pose>
      <axis>
        <xyz>0 0 1</xyz>
      </axis>
    </joint>

    <joint name="back_camera_rgb_optical_joint" type="fixed">
      <parent>back_camera_rgb_frame</parent>
      <child>back_camera_rgb_optical_frame</child>
      <pose>0 0 0 -1.57 0 -1.57</pose>
      <axis>
        <xyz>0 0 1</xyz>
      </axis>
    </joint>

    <link name="back_camera_rgb_optical_frame"/>

    <joint name="back_camera_depth_joint" type="fixed">
      <parent>back_camera_link</parent>
      <child>back_camera_depth_frame</child>
      <pose>0.005 0.028 0.013 -1.57 0 -1.57</pose>
      <axis>
        <xyz>0 0 1</xyz>
      </axis>
    </joint>

    <link name="back_camera_depth_frame">
      <inertial>
        <pose>0.005 0.028 0.013 0 0 0</pose>
        <inertia>
          <ixx>0.001</ixx>
          <ixy>0.000</ixy>
          <ixz>0.000</ixz>
          <iyy>0.001</iyy>
          <iyz>0.000</iyz>
          <izz>0.001</izz>
        </inertia>
        <mass>0.0001</mass>
      </inertial>
    </link>

    <joint name="back_camera_depth_optical_joint" type="fixed">
      <parent>back_camera_depth_frame</parent>
      <child>back_camera_depth_optical_frame</child>
      <pose>0 0 0 -1.57 0 -1.57</pose>
      <axis>
        <xyz>0 0 1</xyz>
      </axis>
    </joint>

    <link name="back_camera_depth_optical_frame">
      <inertial>
        <pose>0 0 0 -1.57 0 -1.57</pose>
        <inertia>
          <ixx>0.001</ixx>
          <ixy>0.000</ixy>
          <ixz>0.000</ixz>
          <iyy>0.001</iyy>
          <iyz>0.000</iyz>
          <izz>0.001</izz>
        </inertia>
        <mass>0.00001</mass>
      </inertial>
    </link>

    <plugin name="dogtooth_diff_drive" filename="libgazebo_ros_diff_drive.so">

      <ros>
        <!-- <namespace>/tb3</namespace> -->
      </ros>

      <update_rate>30</update_rate>

      <!-- wheels -->
      <left_joint>wheel_left_joint</left_joint>
      <right_joint>wheel_right_joint</right_joint>

      <!-- kinematics -->
      <wheel_separation>0.52</wheel_separation>
      <wheel_diameter>0.14</wheel_diameter>

      <!-- limits -->
      <max_wheel_torque>100</max_wheel_torque>
      <max_wheel_acceleration>20.0</max_wheel_acceleration>

      <command_topic>cmd_vel</command_topic>

      <!-- output -->
      <publish_odom>true</publish_odom>
      <publish_odom_tf>false</publish_odom_tf>
      <publish_wheel_tf>false</publish_wheel_tf>

      <odometry_topic>odom</odometry_topic>
      <odometry_frame>odom</odometry_frame>
      <robot_base_frame>base_footprint</robot_base_frame>

    </plugin>

    <plugin name="dogtooth_joint_state" filename="libgazebo_ros_joint_state_publisher.so">
      <ros>
        <remapping>~/out:=joint_states</remapping>
      </ros>
      <update_rate>30</update_rate>
      <joint_name>wheel_left_joint</joint_name>
      <joint_name>wheel_right_joint</joint_name>
    </plugin>    

  </model>
</sdf>
